{\rtf1\ansi\ansicpg1252\cocoartf2639
\cocoatextscaling0\cocoaplatform0{\fonttbl\f0\fswiss\fcharset0 Helvetica;}
{\colortbl;\red255\green255\blue255;}
{\*\expandedcolortbl;;}
\margl1440\margr1440\vieww11520\viewh8400\viewkind0
\pard\tx720\tx1440\tx2160\tx2880\tx3600\tx4320\tx5040\tx5760\tx6480\tx7200\tx7920\tx8640\pardirnatural\partightenfactor0

\f0\fs24 \cf0 mf@MFs-MacBook-Air dotenv %  /usr/bin/env /usr/local/bin/python3 /Users/mf/.vscode/extensions/ms-python.python-2023.4.1/pythonFiles/lib/py\
thon/debugpy/adapter/../../debugpy/launcher 49509 -- /Users/mf/Desktop/IT115/DiscordAWS/dotenv/discord.py \
Traceback (most recent call last):\
  File "/Users/mf/Desktop/IT115/DiscordAWS/dotenv/discord.py", line 4, in <module>\
    import discord\
  File "/Users/mf/Desktop/IT115/DiscordAWS/dotenv/discord.py", line 14, in <module>\
    client = discord.Bot()\
AttributeError: partially initialized module 'discord' has no attribute 'Bot' (most likely due to a circular import)\
mf@MFs-MacBook-Air dotenv % python3 pip install discord \
/Library/Frameworks/Python.framework/Versions/3.10/bin/python3: can't open file '/Users/mf/Desktop/IT115/DiscordAWS/dotenv/pip': [Errno 2] No such file or directory\
mf@MFs-MacBook-Air dotenv % pip install discord.py\
Collecting discord.py\
  Downloading discord.py-2.3.2-py3-none-any.whl.metadata (4.9 kB)\
Collecting aiohttp<4,>=3.7.4 (from discord.py)\
  Downloading aiohttp-3.8.6-cp310-cp310-macosx_11_0_arm64.whl.metadata (7.7 kB)\
Collecting attrs>=17.3.0 (from aiohttp<4,>=3.7.4->discord.py)\
  Downloading attrs-23.1.0-py3-none-any.whl (61 kB)\
     \uc0\u9473 \u9473 \u9473 \u9473 \u9473 \u9473 \u9473 \u9473 \u9473 \u9473 \u9473 \u9473 \u9473 \u9473 \u9473 \u9473 \u9473 \u9473 \u9473 \u9473 \u9473 \u9473 \u9473 \u9473 \u9473 \u9473 \u9473 \u9473 \u9473 \u9473 \u9473 \u9473 \u9473 \u9473 \u9473 \u9473 \u9473 \u9473 \u9473 \u9473  61.2/61.2 kB 667.8 kB/s eta 0:00:00\
Requirement already satisfied: charset-normalizer<4.0,>=2.0 in /Library/Frameworks/Python.framework/Versions/3.10/lib/python3.10/site-packages (from aiohttp<4,>=3.7.4->discord.py) (3.1.0)\
Collecting multidict<7.0,>=4.5 (from aiohttp<4,>=3.7.4->discord.py)\
  Downloading multidict-6.0.4-cp310-cp310-macosx_11_0_arm64.whl (29 kB)\
Collecting async-timeout<5.0,>=4.0.0a3 (from aiohttp<4,>=3.7.4->discord.py)\
  Downloading async_timeout-4.0.3-py3-none-any.whl.metadata (4.2 kB)\
Collecting yarl<2.0,>=1.0 (from aiohttp<4,>=3.7.4->discord.py)\
  Downloading yarl-1.9.2-cp310-cp310-macosx_11_0_arm64.whl (62 kB)\
     \uc0\u9473 \u9473 \u9473 \u9473 \u9473 \u9473 \u9473 \u9473 \u9473 \u9473 \u9473 \u9473 \u9473 \u9473 \u9473 \u9473 \u9473 \u9473 \u9473 \u9473 \u9473 \u9473 \u9473 \u9473 \u9473 \u9473 \u9473 \u9473 \u9473 \u9473 \u9473 \u9473 \u9473 \u9473 \u9473 \u9473 \u9473 \u9473 \u9473 \u9473  62.6/62.6 kB 912.3 kB/s eta 0:00:00\
Collecting frozenlist>=1.1.1 (from aiohttp<4,>=3.7.4->discord.py)\
  Downloading frozenlist-1.4.0-cp310-cp310-macosx_11_0_arm64.whl.metadata (5.2 kB)\
Collecting aiosignal>=1.1.2 (from aiohttp<4,>=3.7.4->discord.py)\
  Downloading aiosignal-1.3.1-py3-none-any.whl (7.6 kB)\
Requirement already satisfied: idna>=2.0 in /Library/Frameworks/Python.framework/Versions/3.10/lib/python3.10/site-packages (from yarl<2.0,>=1.0->aiohttp<4,>=3.7.4->discord.py) (3.4)\
Downloading discord.py-2.3.2-py3-none-any.whl (1.1 MB)\
   \uc0\u9473 \u9473 \u9473 \u9473 \u9473 \u9473 \u9473 \u9473 \u9473 \u9473 \u9473 \u9473 \u9473 \u9473 \u9473 \u9473 \u9473 \u9473 \u9473 \u9473 \u9473 \u9473 \u9473 \u9473 \u9473 \u9473 \u9473 \u9473 \u9473 \u9473 \u9473 \u9473 \u9473 \u9473 \u9473 \u9473 \u9473 \u9473 \u9473 \u9473  1.1/1.1 MB 4.9 MB/s eta 0:00:00\
Downloading aiohttp-3.8.6-cp310-cp310-macosx_11_0_arm64.whl (347 kB)\
   \uc0\u9473 \u9473 \u9473 \u9473 \u9473 \u9473 \u9473 \u9473 \u9473 \u9473 \u9473 \u9473 \u9473 \u9473 \u9473 \u9473 \u9473 \u9473 \u9473 \u9473 \u9473 \u9473 \u9473 \u9473 \u9473 \u9473 \u9473 \u9473 \u9473 \u9473 \u9473 \u9473 \u9473 \u9473 \u9473 \u9473 \u9473 \u9473 \u9473 \u9473  347.7/347.7 kB 6.9 MB/s eta 0:00:00\
Downloading async_timeout-4.0.3-py3-none-any.whl (5.7 kB)\
Downloading frozenlist-1.4.0-cp310-cp310-macosx_11_0_arm64.whl (46 kB)\
   \uc0\u9473 \u9473 \u9473 \u9473 \u9473 \u9473 \u9473 \u9473 \u9473 \u9473 \u9473 \u9473 \u9473 \u9473 \u9473 \u9473 \u9473 \u9473 \u9473 \u9473 \u9473 \u9473 \u9473 \u9473 \u9473 \u9473 \u9473 \u9473 \u9473 \u9473 \u9473 \u9473 \u9473 \u9473 \u9473 \u9473 \u9473 \u9473 \u9473 \u9473  46.0/46.0 kB 1.7 MB/s eta 0:00:00\
Installing collected packages: multidict, frozenlist, attrs, async-timeout, yarl, aiosignal, aiohttp, discord.py\
Successfully installed aiohttp-3.8.6 aiosignal-1.3.1 async-timeout-4.0.3 attrs-23.1.0 discord.py-2.3.2 frozenlist-1.4.0 multidict-6.0.4 yarl-1.9.2\
mf@MFs-MacBook-Air dotenv %  cd /Users/mf/Desktop/IT115/DiscordAWS/dotenv ; /usr/bin/env /usr/local/bin/python3 /Users/mf/.vscode/extensio\
ns/ms-python.python-2023.4.1/pythonFiles/lib/python/debugpy/adapter/../../debugpy/launcher 49821 -- /Users/mf/Desktop/IT115/DiscordAWS/dot\
env/discord.py \
Traceback (most recent call last):\
  File "/Users/mf/Desktop/IT115/DiscordAWS/dotenv/discord.py", line 4, in <module>\
    import discord\
  File "/Users/mf/Desktop/IT115/DiscordAWS/dotenv/discord.py", line 14, in <module>\
    client = discord.Bot()\
AttributeError: partially initialized module 'discord' has no attribute 'Bot' (most likely due to a circular import)\
mf@MFs-MacBook-Air dotenv %  cd /Users/mf/Desktop/IT115/DiscordAWS/dotenv ; /usr/bin/env /usr/local/bin/python3 /Users/mf/.vscode/extensio\
ns/ms-python.python-2023.4.1/pythonFiles/lib/python/debugpy/adapter/../../debugpy/launcher 50014 -- /Users/mf/Desktop/IT115/DiscordAWS/dot\
env/discord.py \
Traceback (most recent call last):\
  File "/Users/mf/Desktop/IT115/DiscordAWS/dotenv/discord.py", line 4, in <module>\
    import discord\
  File "/Users/mf/Desktop/IT115/DiscordAWS/dotenv/discord.py", line 14, in <module>\
    client = discord.Client()\
AttributeError: partially initialized module 'discord' has no attribute 'Client' (most likely due to a circular import)\
mf@MFs-MacBook-Air dotenv % pip install py-cord==2.0.0b1\
Collecting py-cord==2.0.0b1\
  Downloading py_cord-2.0.0b1-py3-none-any.whl (969 kB)\
     \uc0\u9473 \u9473 \u9473 \u9473 \u9473 \u9473 \u9473 \u9473 \u9473 \u9473 \u9473 \u9473 \u9473 \u9473 \u9473 \u9473 \u9473 \u9473 \u9473 \u9473 \u9473 \u9473 \u9473 \u9473 \u9473 \u9473 \u9473 \u9473 \u9473 \u9473 \u9473 \u9473 \u9473 \u9473 \u9473 \u9473 \u9473 \u9473 \u9473 \u9473  969.9/969.9 kB 3.5 MB/s eta 0:00:00\
Requirement already satisfied: aiohttp<3.9.0,>=3.6.0 in /Library/Frameworks/Python.framework/Versions/3.10/lib/python3.10/site-packages (from py-cord==2.0.0b1) (3.8.6)\
Requirement already satisfied: attrs>=17.3.0 in /Library/Frameworks/Python.framework/Versions/3.10/lib/python3.10/site-packages (from aiohttp<3.9.0,>=3.6.0->py-cord==2.0.0b1) (23.1.0)\
Requirement already satisfied: charset-normalizer<4.0,>=2.0 in /Library/Frameworks/Python.framework/Versions/3.10/lib/python3.10/site-packages (from aiohttp<3.9.0,>=3.6.0->py-cord==2.0.0b1) (3.1.0)\
Requirement already satisfied: multidict<7.0,>=4.5 in /Library/Frameworks/Python.framework/Versions/3.10/lib/python3.10/site-packages (from aiohttp<3.9.0,>=3.6.0->py-cord==2.0.0b1) (6.0.4)\
Requirement already satisfied: async-timeout<5.0,>=4.0.0a3 in /Library/Frameworks/Python.framework/Versions/3.10/lib/python3.10/site-packages (from aiohttp<3.9.0,>=3.6.0->py-cord==2.0.0b1) (4.0.3)\
Requirement already satisfied: yarl<2.0,>=1.0 in /Library/Frameworks/Python.framework/Versions/3.10/lib/python3.10/site-packages (from aiohttp<3.9.0,>=3.6.0->py-cord==2.0.0b1) (1.9.2)\
Requirement already satisfied: frozenlist>=1.1.1 in /Library/Frameworks/Python.framework/Versions/3.10/lib/python3.10/site-packages (from aiohttp<3.9.0,>=3.6.0->py-cord==2.0.0b1) (1.4.0)\
Requirement already satisfied: aiosignal>=1.1.2 in /Library/Frameworks/Python.framework/Versions/3.10/lib/python3.10/site-packages (from aiohttp<3.9.0,>=3.6.0->py-cord==2.0.0b1) (1.3.1)\
Requirement already satisfied: idna>=2.0 in /Library/Frameworks/Python.framework/Versions/3.10/lib/python3.10/site-packages (from yarl<2.0,>=1.0->aiohttp<3.9.0,>=3.6.0->py-cord==2.0.0b1) (3.4)\
Installing collected packages: py-cord\
Successfully installed py-cord-2.0.0b1\
mf@MFs-MacBook-Air dotenv %  cd /Users/mf/Desktop/IT115/DiscordAWS/dotenv ; /usr/bin/env /usr/local/bin/python3 /Users/mf/.vscode/extensio\
ns/ms-python.python-2023.4.1/pythonFiles/lib/python/debugpy/adapter/../../debugpy/launcher 50142 -- /Users/mf/Desktop/IT115/DiscordAWS/dot\
env/discord.py \
Traceback (most recent call last):\
  File "/Users/mf/Desktop/IT115/DiscordAWS/dotenv/discord.py", line 4, in <module>\
    import discord\
  File "/Users/mf/Desktop/IT115/DiscordAWS/dotenv/discord.py", line 14, in <module>\
    client = discord.Client()\
AttributeError: partially initialized module 'discord' has no attribute 'Client' (most likely due to a circular import)\
mf@MFs-MacBook-Air dotenv %  cd /Users/mf/Desktop/IT115/DiscordAWS/dotenv ; /usr/bin/env /usr/local/bin/python3 /Users/mf/.vscode/extensio\
ns/ms-python.python-2023.4.1/pythonFiles/lib/python/debugpy/adapter/../../debugpy/launcher 50298 -- /Users/mf/Desktop/IT115/DiscordAWS/dot\
env/discord.py \
Traceback (most recent call last):\
  File "/Users/mf/Desktop/IT115/DiscordAWS/dotenv/discord.py", line 4, in <module>\
    import discord\
  File "/Users/mf/Desktop/IT115/DiscordAWS/dotenv/discord.py", line 14, in <module>\
    client = discord.Bot()\
AttributeError: partially initialized module 'discord' has no attribute 'Bot' (most likely due to a circular import)\
mf@MFs-MacBook-Air dotenv %  cd /Users/mf/Desktop/IT115/DiscordAWS/dotenv ; /usr/bin/env /usr/local/bin/python3 /Users/mf/.vscode/extensio\
ns/ms-python.python-2023.4.1/pythonFiles/lib/python/debugpy/adapter/../../debugpy/launcher 50466 -- /Users/mf/Desktop/IT115/DiscordAWS/dot\
env/discord.py \
Traceback (most recent call last):\
  File "/Users/mf/Desktop/IT115/DiscordAWS/dotenv/discord.py", line 4, in <module>\
    import discord\
  File "/Users/mf/Desktop/IT115/DiscordAWS/dotenv/discord.py", line 5, in <module>\
    from discord.ext import commands\
ModuleNotFoundError: No module named 'discord.ext'; 'discord' is not a package\
mf@MFs-MacBook-Air dotenv %  cd /Users/mf/Desktop/IT115/DiscordAWS/dotenv ; /usr/bin/env /usr/local/bin/python3 /Users/mf/.vscode/extensio\
ns/ms-python.python-2023.4.1/pythonFiles/lib/python/debugpy/adapter/../../debugpy/launcher 50603 -- /Users/mf/Desktop/IT115/DiscordAWS/dot\
env/main.py \
Traceback (most recent call last):\
  File "/Users/mf/Desktop/IT115/DiscordAWS/dotenv/main.py", line 4, in <module>\
    import discord\
  File "/Users/mf/Desktop/IT115/DiscordAWS/dotenv/discord.py", line 5, in <module>\
    from discord.ext import commands\
ModuleNotFoundError: No module named 'discord.ext'; 'discord' is not a package\
mf@MFs-MacBook-Air dotenv %  cd /Users/mf/Desktop/IT115/DiscordAWS/dotenv ; /usr/bin/env /usr/local/bin/python3 /Users/mf/.vscode/extensio\
ns/ms-python.python-2023.4.1/pythonFiles/lib/python/debugpy/adapter/../../debugpy/launcher 50632 -- /Users/mf/Desktop/IT115/DiscordAWS/dot\
env/main.py \
Traceback (most recent call last):\
  File "/Users/mf/Desktop/IT115/DiscordAWS/dotenv/main.py", line 4, in <module>\
    import discord\
  File "/Users/mf/Desktop/IT115/DiscordAWS/dotenv/discord.py", line 5, in <module>\
    from discord.ext import commands\
ModuleNotFoundError: No module named 'discord.ext'; 'discord' is not a package\
mf@MFs-MacBook-Air dotenv %  cd /Users/mf/Desktop/IT115/DiscordAWS/dotenv ; /usr/bin/env /usr/local/bin/python3 /Users/mf/.vscode/extensio\
ns/ms-python.python-2023.4.1/pythonFiles/lib/python/debugpy/adapter/../../debugpy/launcher 50657 -- /Users/mf/Desktop/IT115/DiscordAWS/dot\
env/main.py \
Traceback (most recent call last):\
  File "/Users/mf/Desktop/IT115/DiscordAWS/dotenv/main.py", line 4, in <module>\
    import discord\
  File "/Users/mf/Desktop/IT115/DiscordAWS/dotenv/discord.py", line 5, in <module>\
    from discord.ext import commands\
ModuleNotFoundError: No module named 'discord.ext'; 'discord' is not a package\
mf@MFs-MacBook-Air dotenv %  cd /Users/mf/Desktop/IT115/DiscordAWS/dotenv ; /usr/bin/env /usr/local/bin/python3 /Users/mf/.vscode/extensio\
ns/ms-python.python-2023.4.1/pythonFiles/lib/python/debugpy/adapter/../../debugpy/launcher 50678 -- /Users/mf/Desktop/IT115/DiscordAWS/dot\
env/main.py \
Traceback (most recent call last):\
  File "/Users/mf/Desktop/IT115/DiscordAWS/dotenv/main.py", line 4, in <module>\
    import discord\
  File "/Users/mf/Desktop/IT115/DiscordAWS/dotenv/discord.py", line 5, in <module>\
    from discord.ext import commands\
ModuleNotFoundError: No module named 'discord.ext'; 'discord' is not a package\
mf@MFs-MacBook-Air dotenv %  cd /Users/mf/Desktop/IT115/DiscordAWS/dotenv ; /usr/bin/env /usr/local/bin/python3 /Users/mf/.vscode/extensio\
ns/ms-python.python-2023.4.1/pythonFiles/lib/python/debugpy/adapter/../../debugpy/launcher 50695 -- /Users/mf/Desktop/IT115/DiscordAWS/dot\
env/main.py \
Traceback (most recent call last):\
  File "/Users/mf/Desktop/IT115/DiscordAWS/dotenv/main.py", line 4, in <module>\
    import discord\
  File "/Users/mf/Desktop/IT115/DiscordAWS/dotenv/discord.py", line 5, in <module>\
    from discord.ext import commands\
ModuleNotFoundError: No module named 'discord.ext'; 'discord' is not a package\
mf@MFs-MacBook-Air dotenv %  cd /Users/mf/Desktop/IT115/DiscordAWS ; /usr/bin/env /usr/local/bin/python3 /Users/mf/.vscode/extensions/ms-p\
ython.python-2023.4.1/pythonFiles/lib/python/debugpy/adapter/../../debugpy/launcher 50730 -- /Users/mf/Desktop/IT115/DiscordAWS/main.py \
Traceback (most recent call last):\
  File "/Users/mf/Desktop/IT115/DiscordAWS/main.py", line 4, in <module>\
    import discord\
  File "/Users/mf/Desktop/IT115/DiscordAWS/discord.py", line 14, in <module>\
    client = discord.Bot()\
AttributeError: partially initialized module 'discord' has no attribute 'Bot' (most likely due to a circular import)\
mf@MFs-MacBook-Air DiscordAWS %  cd /Users/mf/Desktop/IT115/DiscordAWS ; /usr/bin/env /usr/local/bin/python3 /Users/mf/.vscode/extensions/\
ms-python.python-2023.4.1/pythonFiles/lib/python/debugpy/adapter/../../debugpy/launcher 50768 -- /Users/mf/Desktop/IT115/DiscordAWS/main.p\
y \
mf@MFs-MacBook-Air DiscordAWS %  cd /Users/mf/Desktop/IT115/DiscordAWS ; /usr/bin/env /usr/local/bin/python3 /Users/mf/.vscode/extensions/\
ms-python.python-2023.4.1/pythonFiles/lib/python/debugpy/adapter/../../debugpy/launcher 50805 -- /Users/mf/Desktop/IT115/DiscordAWS/discor\
d.py \
Traceback (most recent call last):\
  File "/Users/mf/Desktop/IT115/DiscordAWS/discord.py", line 4, in <module>\
    import discord\
  File "/Users/mf/Desktop/IT115/DiscordAWS/discord.py", line 14, in <module>\
    client = discord.client()\
AttributeError: partially initialized module 'discord' has no attribute 'client' (most likely due to a circular import)\
mf@MFs-MacBook-Air DiscordAWS %  cd /Users/mf/Desktop/IT115/DiscordAWS ; /usr/bin/env /usr/local/bin/python3 /Users/mf/.vscode/extensions/\
ms-python.python-2023.4.1/pythonFiles/lib/python/debugpy/adapter/../../debugpy/launcher 50820 -- /Users/mf/Desktop/IT115/DiscordAWS/discor\
d.py \
Traceback (most recent call last):\
  File "/Users/mf/Desktop/IT115/DiscordAWS/discord.py", line 4, in <module>\
    import discord\
  File "/Users/mf/Desktop/IT115/DiscordAWS/discord.py", line 14, in <module>\
    client = discord.Client()\
AttributeError: partially initialized module 'discord' has no attribute 'Client' (most likely due to a circular import)\
mf@MFs-MacBook-Air DiscordAWS %  cd /Users/mf/Desktop/IT115/DiscordAWS ; /usr/bin/env /usr/local/bin/python3 /Users/mf/.vscode/extensions/\
ms-python.python-2023.4.1/pythonFiles/lib/python/debugpy/adapter/../../debugpy/launcher 50922 -- /Users/mf/Desktop/IT115/DiscordAWS/main2E\
xample.py \
Traceback (most recent call last):\
  File "/Users/mf/Desktop/IT115/DiscordAWS/main2Example.py", line 2, in <module>\
    import discord\
  File "/Users/mf/Desktop/IT115/DiscordAWS/discord.py", line 14, in <module>\
    client = discord.Client()\
AttributeError: partially initialized module 'discord' has no attribute 'Client' (most likely due to a circular import)\
mf@MFs-MacBook-Air DiscordAWS % ls\
__pycache__     discord         discord.py      dotenv          main.py         main2Example.py\
mf@MFs-MacBook-Air DiscordAWS % py -3 -m pip install -U discord.py\
zsh: command not found: py\
mf@MFs-MacBook-Air DiscordAWS % python3 -m pip install -U discord.py \
Requirement already satisfied: discord.py in /Library/Frameworks/Python.framework/Versions/3.10/lib/python3.10/site-packages (2.3.2)\
Requirement already satisfied: aiohttp<4,>=3.7.4 in /Library/Frameworks/Python.framework/Versions/3.10/lib/python3.10/site-packages (from discord.py) (3.8.6)\
Requirement already satisfied: attrs>=17.3.0 in /Library/Frameworks/Python.framework/Versions/3.10/lib/python3.10/site-packages (from aiohttp<4,>=3.7.4->discord.py) (23.1.0)\
Requirement already satisfied: charset-normalizer<4.0,>=2.0 in /Library/Frameworks/Python.framework/Versions/3.10/lib/python3.10/site-packages (from aiohttp<4,>=3.7.4->discord.py) (3.1.0)\
Requirement already satisfied: multidict<7.0,>=4.5 in /Library/Frameworks/Python.framework/Versions/3.10/lib/python3.10/site-packages (from aiohttp<4,>=3.7.4->discord.py) (6.0.4)\
Requirement already satisfied: async-timeout<5.0,>=4.0.0a3 in /Library/Frameworks/Python.framework/Versions/3.10/lib/python3.10/site-packages (from aiohttp<4,>=3.7.4->discord.py) (4.0.3)\
Requirement already satisfied: yarl<2.0,>=1.0 in /Library/Frameworks/Python.framework/Versions/3.10/lib/python3.10/site-packages (from aiohttp<4,>=3.7.4->discord.py) (1.9.2)\
Requirement already satisfied: frozenlist>=1.1.1 in /Library/Frameworks/Python.framework/Versions/3.10/lib/python3.10/site-packages (from aiohttp<4,>=3.7.4->discord.py) (1.4.0)\
Requirement already satisfied: aiosignal>=1.1.2 in /Library/Frameworks/Python.framework/Versions/3.10/lib/python3.10/site-packages (from aiohttp<4,>=3.7.4->discord.py) (1.3.1)\
Requirement already satisfied: idna>=2.0 in /Library/Frameworks/Python.framework/Versions/3.10/lib/python3.10/site-packages (from yarl<2.0,>=1.0->aiohttp<4,>=3.7.4->discord.py) (3.4)\
mf@MFs-MacBook-Air DiscordAWS %  cd /Users/mf/Desktop/IT115/DiscordAWS ; /usr/bin/env /usr/local/bin/python3 /Users/mf/.vscode/extensions/\
ms-python.python-2023.4.1/pythonFiles/lib/python/debugpy/adapter/../../debugpy/launcher 51188 -- /Users/mf/Desktop/IT115/DiscordAWS/main2E\
xample.py \
Traceback (most recent call last):\
  File "/Library/Frameworks/Python.framework/Versions/3.10/lib/python3.10/site-packages/aiohttp/connector.py", line 980, in _wrap_create_connection\
    return await self._loop.create_connection(*args, **kwargs)  # type: ignore[return-value]  # noqa\
  File "/Library/Frameworks/Python.framework/Versions/3.10/lib/python3.10/asyncio/base_events.py", line 1103, in create_connection\
    transport, protocol = await self._create_connection_transport(\
  File "/Library/Frameworks/Python.framework/Versions/3.10/lib/python3.10/asyncio/base_events.py", line 1133, in _create_connection_transport\
    await waiter\
  File "/Library/Frameworks/Python.framework/Versions/3.10/lib/python3.10/asyncio/sslproto.py", line 534, in data_received\
    ssldata, appdata = self._sslpipe.feed_ssldata(data)\
  File "/Library/Frameworks/Python.framework/Versions/3.10/lib/python3.10/asyncio/sslproto.py", line 188, in feed_ssldata\
    self._sslobj.do_handshake()\
  File "/Library/Frameworks/Python.framework/Versions/3.10/lib/python3.10/ssl.py", line 975, in do_handshake\
    self._sslobj.do_handshake()\
ssl.SSLCertVerificationError: [SSL: CERTIFICATE_VERIFY_FAILED] certificate verify failed: unable to get local issuer certificate (_ssl.c:1007)\
\
The above exception was the direct cause of the following exception:\
\
Traceback (most recent call last):\
  File "/Users/mf/Desktop/IT115/DiscordAWS/main2Example.py", line 33, in <module>\
    bot.run("MTE2ODE5NTkyNzU2NDA5NTQ4OA.GUXJH1.IPKId6PtF93NWc6RX3xRicV1b9lan_2JbqhEuY")\
  File "/Library/Frameworks/Python.framework/Versions/3.10/lib/python3.10/site-packages/discord/client.py", line 668, in run\
    return future.result()\
  File "/Library/Frameworks/Python.framework/Versions/3.10/lib/python3.10/site-packages/discord/client.py", line 647, in runner\
    await self.start(*args, **kwargs)\
  File "/Library/Frameworks/Python.framework/Versions/3.10/lib/python3.10/site-packages/discord/client.py", line 610, in start\
    await self.login(token)\
  File "/Library/Frameworks/Python.framework/Versions/3.10/lib/python3.10/site-packages/discord/client.py", line 478, in login\
    data = await self.http.static_login(token.strip())\
  File "/Library/Frameworks/Python.framework/Versions/3.10/lib/python3.10/site-packages/discord/http.py", line 383, in static_login\
    data = await self.request(Route('GET', '/users/@me'))\
  File "/Library/Frameworks/Python.framework/Versions/3.10/lib/python3.10/site-packages/discord/http.py", line 276, in request\
    async with self.__session.request(method, url, **kwargs) as response:\
  File "/Library/Frameworks/Python.framework/Versions/3.10/lib/python3.10/site-packages/aiohttp/client.py", line 1167, in __aenter__\
    self._resp = await self._coro\
  File "/Library/Frameworks/Python.framework/Versions/3.10/lib/python3.10/site-packages/aiohttp/client.py", line 562, in _request\
    conn = await self._connector.connect(\
  File "/Library/Frameworks/Python.framework/Versions/3.10/lib/python3.10/site-packages/aiohttp/connector.py", line 540, in connect\
    proto = await self._create_connection(req, traces, timeout)\
  File "/Library/Frameworks/Python.framework/Versions/3.10/lib/python3.10/site-packages/aiohttp/connector.py", line 901, in _create_connection\
    _, proto = await self._create_direct_connection(req, traces, timeout)\
  File "/Library/Frameworks/Python.framework/Versions/3.10/lib/python3.10/site-packages/aiohttp/connector.py", line 1209, in _create_direct_connection\
    raise last_exc\
  File "/Library/Frameworks/Python.framework/Versions/3.10/lib/python3.10/site-packages/aiohttp/connector.py", line 1178, in _create_direct_connection\
    transp, proto = await self._wrap_create_connection(\
  File "/Library/Frameworks/Python.framework/Versions/3.10/lib/python3.10/site-packages/aiohttp/connector.py", line 982, in _wrap_create_connection\
    raise ClientConnectorCertificateError(req.connection_key, exc) from exc\
aiohttp.client_exceptions.ClientConnectorCertificateError: Cannot connect to host discord.com:443 ssl:True [SSLCertVerificationError: (1, '[SSL: CERTIFICATE_VERIFY_FAILED] certificate verify failed: unable to get local issuer certificate (_ssl.c:1007)')]\
mf@MFs-MacBook-Air DiscordAWS %  cd /Users/mf/Desktop/IT115/DiscordAWS ; /usr/bin/env /usr/local/bin/python3 /Users/mf/.vscode/extensions/\
ms-python.python-2023.4.1/pythonFiles/lib/python/debugpy/adapter/../../debugpy/launcher 51259 -- /Users/mf/Desktop/IT115/DiscordAWS/main.p\
y \
Traceback (most recent call last):\
  File "/Users/mf/Desktop/IT115/DiscordAWS/main.py", line 65, in <module>\
    client.run(token)\
  File "/Library/Frameworks/Python.framework/Versions/3.10/lib/python3.10/site-packages/discord/client.py", line 668, in run\
    return future.result()\
  File "/Library/Frameworks/Python.framework/Versions/3.10/lib/python3.10/site-packages/discord/client.py", line 647, in runner\
    await self.start(*args, **kwargs)\
  File "/Library/Frameworks/Python.framework/Versions/3.10/lib/python3.10/site-packages/discord/client.py", line 610, in start\
    await self.login(token)\
  File "/Library/Frameworks/Python.framework/Versions/3.10/lib/python3.10/site-packages/discord/client.py", line 474, in login\
    raise TypeError(f"token must be of type str, not \{token.__class__.__name__\}")\
TypeError: token must be of type str, not NoneType\
mf@MFs-MacBook-Air DiscordAWS %  cd /Users/mf/Desktop/IT115/DiscordAWS ; /usr/bin/env /usr/local/bin/python3 /Users/mf/.vscode/extensions/\
ms-python.python-2023.4.1/pythonFiles/lib/python/debugpy/adapter/../../debugpy/launcher 51299 -- /Users/mf/Desktop/IT115/DiscordAWS/main.p\
y \
Traceback (most recent call last):\
  File "/Library/Frameworks/Python.framework/Versions/3.10/lib/python3.10/site-packages/aiohttp/connector.py", line 980, in _wrap_create_connection\
    return await self._loop.create_connection(*args, **kwargs)  # type: ignore[return-value]  # noqa\
  File "/Library/Frameworks/Python.framework/Versions/3.10/lib/python3.10/asyncio/base_events.py", line 1103, in create_connection\
    transport, protocol = await self._create_connection_transport(\
  File "/Library/Frameworks/Python.framework/Versions/3.10/lib/python3.10/asyncio/base_events.py", line 1133, in _create_connection_transport\
    await waiter\
  File "/Library/Frameworks/Python.framework/Versions/3.10/lib/python3.10/asyncio/sslproto.py", line 534, in data_received\
    ssldata, appdata = self._sslpipe.feed_ssldata(data)\
  File "/Library/Frameworks/Python.framework/Versions/3.10/lib/python3.10/asyncio/sslproto.py", line 188, in feed_ssldata\
    self._sslobj.do_handshake()\
  File "/Library/Frameworks/Python.framework/Versions/3.10/lib/python3.10/ssl.py", line 975, in do_handshake\
    self._sslobj.do_handshake()\
ssl.SSLCertVerificationError: [SSL: CERTIFICATE_VERIFY_FAILED] certificate verify failed: unable to get local issuer certificate (_ssl.c:1007)\
\
The above exception was the direct cause of the following exception:\
\
Traceback (most recent call last):\
  File "/Users/mf/Desktop/IT115/DiscordAWS/main.py", line 65, in <module>\
    client.run(token)\
  File "/Library/Frameworks/Python.framework/Versions/3.10/lib/python3.10/site-packages/discord/client.py", line 668, in run\
    return future.result()\
  File "/Library/Frameworks/Python.framework/Versions/3.10/lib/python3.10/site-packages/discord/client.py", line 647, in runner\
    await self.start(*args, **kwargs)\
  File "/Library/Frameworks/Python.framework/Versions/3.10/lib/python3.10/site-packages/discord/client.py", line 610, in start\
    await self.login(token)\
  File "/Library/Frameworks/Python.framework/Versions/3.10/lib/python3.10/site-packages/discord/client.py", line 478, in login\
    data = await self.http.static_login(token.strip())\
  File "/Library/Frameworks/Python.framework/Versions/3.10/lib/python3.10/site-packages/discord/http.py", line 383, in static_login\
    data = await self.request(Route('GET', '/users/@me'))\
  File "/Library/Frameworks/Python.framework/Versions/3.10/lib/python3.10/site-packages/discord/http.py", line 276, in request\
    async with self.__session.request(method, url, **kwargs) as response:\
  File "/Library/Frameworks/Python.framework/Versions/3.10/lib/python3.10/site-packages/aiohttp/client.py", line 1167, in __aenter__\
    self._resp = await self._coro\
  File "/Library/Frameworks/Python.framework/Versions/3.10/lib/python3.10/site-packages/aiohttp/client.py", line 562, in _request\
    conn = await self._connector.connect(\
  File "/Library/Frameworks/Python.framework/Versions/3.10/lib/python3.10/site-packages/aiohttp/connector.py", line 540, in connect\
    proto = await self._create_connection(req, traces, timeout)\
  File "/Library/Frameworks/Python.framework/Versions/3.10/lib/python3.10/site-packages/aiohttp/connector.py", line 901, in _create_connection\
    _, proto = await self._create_direct_connection(req, traces, timeout)\
  File "/Library/Frameworks/Python.framework/Versions/3.10/lib/python3.10/site-packages/aiohttp/connector.py", line 1209, in _create_direct_connection\
    raise last_exc\
  File "/Library/Frameworks/Python.framework/Versions/3.10/lib/python3.10/site-packages/aiohttp/connector.py", line 1178, in _create_direct_connection\
    transp, proto = await self._wrap_create_connection(\
  File "/Library/Frameworks/Python.framework/Versions/3.10/lib/python3.10/site-packages/aiohttp/connector.py", line 982, in _wrap_create_connection\
    raise ClientConnectorCertificateError(req.connection_key, exc) from exc\
aiohttp.client_exceptions.ClientConnectorCertificateError: Cannot connect to host discord.com:443 ssl:True [SSLCertVerificationError: (1, '[SSL: CERTIFICATE_VERIFY_FAILED] certificate verify failed: unable to get local issuer certificate (_ssl.c:1007)')]\
mf@MFs-MacBook-Air DiscordAWS %  cd /Users/mf/Desktop/IT115/DiscordAWS ; /usr/bin/env /usr/local/bin/python3 /Users/mf/.vscode/extensions/\
ms-python.python-2023.4.1/pythonFiles/lib/python/debugpy/adapter/../../debugpy/launcher 51915 -- /Users/mf/Desktop/IT115/DiscordAWS/main.p\
y \
Traceback (most recent call last):\
  File "/Library/Frameworks/Python.framework/Versions/3.10/lib/python3.10/site-packages/aiohttp/connector.py", line 980, in _wrap_create_connection\
    return await self._loop.create_connection(*args, **kwargs)  # type: ignore[return-value]  # noqa\
  File "/Library/Frameworks/Python.framework/Versions/3.10/lib/python3.10/asyncio/base_events.py", line 1103, in create_connection\
    transport, protocol = await self._create_connection_transport(\
  File "/Library/Frameworks/Python.framework/Versions/3.10/lib/python3.10/asyncio/base_events.py", line 1133, in _create_connection_transport\
    await waiter\
  File "/Library/Frameworks/Python.framework/Versions/3.10/lib/python3.10/asyncio/sslproto.py", line 534, in data_received\
    ssldata, appdata = self._sslpipe.feed_ssldata(data)\
  File "/Library/Frameworks/Python.framework/Versions/3.10/lib/python3.10/asyncio/sslproto.py", line 188, in feed_ssldata\
    self._sslobj.do_handshake()\
  File "/Library/Frameworks/Python.framework/Versions/3.10/lib/python3.10/ssl.py", line 975, in do_handshake\
    self._sslobj.do_handshake()\
ssl.SSLCertVerificationError: [SSL: CERTIFICATE_VERIFY_FAILED] certificate verify failed: unable to get local issuer certificate (_ssl.c:1007)\
\
The above exception was the direct cause of the following exception:\
\
Traceback (most recent call last):\
  File "/Users/mf/Desktop/IT115/DiscordAWS/main.py", line 65, in <module>\
    client.run(token)\
  File "/Library/Frameworks/Python.framework/Versions/3.10/lib/python3.10/site-packages/discord/client.py", line 668, in run\
    return future.result()\
  File "/Library/Frameworks/Python.framework/Versions/3.10/lib/python3.10/site-packages/discord/client.py", line 647, in runner\
    await self.start(*args, **kwargs)\
  File "/Library/Frameworks/Python.framework/Versions/3.10/lib/python3.10/site-packages/discord/client.py", line 610, in start\
    await self.login(token)\
  File "/Library/Frameworks/Python.framework/Versions/3.10/lib/python3.10/site-packages/discord/client.py", line 478, in login\
    data = await self.http.static_login(token.strip())\
  File "/Library/Frameworks/Python.framework/Versions/3.10/lib/python3.10/site-packages/discord/http.py", line 383, in static_login\
    data = await self.request(Route('GET', '/users/@me'))\
  File "/Library/Frameworks/Python.framework/Versions/3.10/lib/python3.10/site-packages/discord/http.py", line 276, in request\
    async with self.__session.request(method, url, **kwargs) as response:\
  File "/Library/Frameworks/Python.framework/Versions/3.10/lib/python3.10/site-packages/aiohttp/client.py", line 1167, in __aenter__\
    self._resp = await self._coro\
  File "/Library/Frameworks/Python.framework/Versions/3.10/lib/python3.10/site-packages/aiohttp/client.py", line 562, in _request\
    conn = await self._connector.connect(\
  File "/Library/Frameworks/Python.framework/Versions/3.10/lib/python3.10/site-packages/aiohttp/connector.py", line 540, in connect\
    proto = await self._create_connection(req, traces, timeout)\
  File "/Library/Frameworks/Python.framework/Versions/3.10/lib/python3.10/site-packages/aiohttp/connector.py", line 901, in _create_connection\
    _, proto = await self._create_direct_connection(req, traces, timeout)\
  File "/Library/Frameworks/Python.framework/Versions/3.10/lib/python3.10/site-packages/aiohttp/connector.py", line 1209, in _create_direct_connection\
    raise last_exc\
  File "/Library/Frameworks/Python.framework/Versions/3.10/lib/python3.10/site-packages/aiohttp/connector.py", line 1178, in _create_direct_connection\
    transp, proto = await self._wrap_create_connection(\
  File "/Library/Frameworks/Python.framework/Versions/3.10/lib/python3.10/site-packages/aiohttp/connector.py", line 982, in _wrap_create_connection\
    raise ClientConnectorCertificateError(req.connection_key, exc) from exc\
aiohttp.client_exceptions.ClientConnectorCertificateError: Cannot connect to host discord.com:443 ssl:True [SSLCertVerificationError: (1, '[SSL: CERTIFICATE_VERIFY_FAILED] certificate verify failed: unable to get local issuer certificate (_ssl.c:1007)')]\
mf@MFs-MacBook-Air DiscordAWS %  cd /Users/mf/Desktop/IT115/DiscordAWS ; /usr/bin/env /usr/local/bin/python3 /Users/mf/.vscode/extensions/\
ms-python.python-2023.4.1/pythonFiles/lib/python/debugpy/adapter/../../debugpy/launcher 52120 -- /Users/mf/Desktop/IT115/DiscordAWS/main2E\
xample.py \
Traceback (most recent call last):\
  File "/Library/Frameworks/Python.framework/Versions/3.10/lib/python3.10/site-packages/aiohttp/connector.py", line 980, in _wrap_create_connection\
    return await self._loop.create_connection(*args, **kwargs)  # type: ignore[return-value]  # noqa\
  File "/Library/Frameworks/Python.framework/Versions/3.10/lib/python3.10/asyncio/base_events.py", line 1103, in create_connection\
    transport, protocol = await self._create_connection_transport(\
  File "/Library/Frameworks/Python.framework/Versions/3.10/lib/python3.10/asyncio/base_events.py", line 1133, in _create_connection_transport\
    await waiter\
  File "/Library/Frameworks/Python.framework/Versions/3.10/lib/python3.10/asyncio/sslproto.py", line 534, in data_received\
    ssldata, appdata = self._sslpipe.feed_ssldata(data)\
  File "/Library/Frameworks/Python.framework/Versions/3.10/lib/python3.10/asyncio/sslproto.py", line 188, in feed_ssldata\
    self._sslobj.do_handshake()\
  File "/Library/Frameworks/Python.framework/Versions/3.10/lib/python3.10/ssl.py", line 975, in do_handshake\
    self._sslobj.do_handshake()\
ssl.SSLCertVerificationError: [SSL: CERTIFICATE_VERIFY_FAILED] certificate verify failed: unable to get local issuer certificate (_ssl.c:1007)\
\
The above exception was the direct cause of the following exception:\
\
Traceback (most recent call last):\
  File "/Users/mf/Desktop/IT115/DiscordAWS/main2Example.py", line 33, in <module>\
    bot.run("MTE2ODE5NTkyNzU2NDA5NTQ4OA.GTTgzQ._UND-IQMgR1HDlOPVEQtpas-y665DBaLLV2qas")\
  File "/Library/Frameworks/Python.framework/Versions/3.10/lib/python3.10/site-packages/discord/client.py", line 668, in run\
    return future.result()\
  File "/Library/Frameworks/Python.framework/Versions/3.10/lib/python3.10/site-packages/discord/client.py", line 647, in runner\
    await self.start(*args, **kwargs)\
  File "/Library/Frameworks/Python.framework/Versions/3.10/lib/python3.10/site-packages/discord/client.py", line 610, in start\
    await self.login(token)\
  File "/Library/Frameworks/Python.framework/Versions/3.10/lib/python3.10/site-packages/discord/client.py", line 478, in login\
    data = await self.http.static_login(token.strip())\
  File "/Library/Frameworks/Python.framework/Versions/3.10/lib/python3.10/site-packages/discord/http.py", line 383, in static_login\
    data = await self.request(Route('GET', '/users/@me'))\
  File "/Library/Frameworks/Python.framework/Versions/3.10/lib/python3.10/site-packages/discord/http.py", line 276, in request\
    async with self.__session.request(method, url, **kwargs) as response:\
  File "/Library/Frameworks/Python.framework/Versions/3.10/lib/python3.10/site-packages/aiohttp/client.py", line 1167, in __aenter__\
    self._resp = await self._coro\
  File "/Library/Frameworks/Python.framework/Versions/3.10/lib/python3.10/site-packages/aiohttp/client.py", line 562, in _request\
    conn = await self._connector.connect(\
  File "/Library/Frameworks/Python.framework/Versions/3.10/lib/python3.10/site-packages/aiohttp/connector.py", line 540, in connect\
    proto = await self._create_connection(req, traces, timeout)\
  File "/Library/Frameworks/Python.framework/Versions/3.10/lib/python3.10/site-packages/aiohttp/connector.py", line 901, in _create_connection\
    _, proto = await self._create_direct_connection(req, traces, timeout)\
  File "/Library/Frameworks/Python.framework/Versions/3.10/lib/python3.10/site-packages/aiohttp/connector.py", line 1209, in _create_direct_connection\
    raise last_exc\
  File "/Library/Frameworks/Python.framework/Versions/3.10/lib/python3.10/site-packages/aiohttp/connector.py", line 1178, in _create_direct_connection\
    transp, proto = await self._wrap_create_connection(\
  File "/Library/Frameworks/Python.framework/Versions/3.10/lib/python3.10/site-packages/aiohttp/connector.py", line 982, in _wrap_create_connection\
    raise ClientConnectorCertificateError(req.connection_key, exc) from exc\
aiohttp.client_exceptions.ClientConnectorCertificateError: Cannot connect to host discord.com:443 ssl:True [SSLCertVerificationError: (1, '[SSL: CERTIFICATE_VERIFY_FAILED] certificate verify failed: unable to get local issuer certificate (_ssl.c:1007)')]\
mf@MFs-MacBook-Air DiscordAWS %  cd /Users/mf/Desktop/IT115/DiscordAWS ; /usr/bin/env /usr/local/bin/python3 /Users/mf/.vscode/extensions/\
ms-python.python-2023.4.1/pythonFiles/lib/python/debugpy/adapter/../../debugpy/launcher 52166 -- /Users/mf/Desktop/IT115/DiscordAWS/main.p\
y \
Traceback (most recent call last):\
  File "/Library/Frameworks/Python.framework/Versions/3.10/lib/python3.10/site-packages/aiohttp/connector.py", line 980, in _wrap_create_connection\
    return await self._loop.create_connection(*args, **kwargs)  # type: ignore[return-value]  # noqa\
  File "/Library/Frameworks/Python.framework/Versions/3.10/lib/python3.10/asyncio/base_events.py", line 1103, in create_connection\
    transport, protocol = await self._create_connection_transport(\
  File "/Library/Frameworks/Python.framework/Versions/3.10/lib/python3.10/asyncio/base_events.py", line 1133, in _create_connection_transport\
    await waiter\
  File "/Library/Frameworks/Python.framework/Versions/3.10/lib/python3.10/asyncio/sslproto.py", line 534, in data_received\
    ssldata, appdata = self._sslpipe.feed_ssldata(data)\
  File "/Library/Frameworks/Python.framework/Versions/3.10/lib/python3.10/asyncio/sslproto.py", line 188, in feed_ssldata\
    self._sslobj.do_handshake()\
  File "/Library/Frameworks/Python.framework/Versions/3.10/lib/python3.10/ssl.py", line 975, in do_handshake\
    self._sslobj.do_handshake()\
ssl.SSLCertVerificationError: [SSL: CERTIFICATE_VERIFY_FAILED] certificate verify failed: unable to get local issuer certificate (_ssl.c:1007)\
\
The above exception was the direct cause of the following exception:\
\
Traceback (most recent call last):\
  File "/Users/mf/Desktop/IT115/DiscordAWS/main.py", line 65, in <module>\
    client.run(token)\
  File "/Library/Frameworks/Python.framework/Versions/3.10/lib/python3.10/site-packages/discord/client.py", line 668, in run\
    return future.result()\
  File "/Library/Frameworks/Python.framework/Versions/3.10/lib/python3.10/site-packages/discord/client.py", line 647, in runner\
    await self.start(*args, **kwargs)\
  File "/Library/Frameworks/Python.framework/Versions/3.10/lib/python3.10/site-packages/discord/client.py", line 610, in start\
    await self.login(token)\
  File "/Library/Frameworks/Python.framework/Versions/3.10/lib/python3.10/site-packages/discord/client.py", line 478, in login\
    data = await self.http.static_login(token.strip())\
  File "/Library/Frameworks/Python.framework/Versions/3.10/lib/python3.10/site-packages/discord/http.py", line 383, in static_login\
    data = await self.request(Route('GET', '/users/@me'))\
  File "/Library/Frameworks/Python.framework/Versions/3.10/lib/python3.10/site-packages/discord/http.py", line 276, in request\
    async with self.__session.request(method, url, **kwargs) as response:\
  File "/Library/Frameworks/Python.framework/Versions/3.10/lib/python3.10/site-packages/aiohttp/client.py", line 1167, in __aenter__\
    self._resp = await self._coro\
  File "/Library/Frameworks/Python.framework/Versions/3.10/lib/python3.10/site-packages/aiohttp/client.py", line 562, in _request\
    conn = await self._connector.connect(\
  File "/Library/Frameworks/Python.framework/Versions/3.10/lib/python3.10/site-packages/aiohttp/connector.py", line 540, in connect\
    proto = await self._create_connection(req, traces, timeout)\
  File "/Library/Frameworks/Python.framework/Versions/3.10/lib/python3.10/site-packages/aiohttp/connector.py", line 901, in _create_connection\
    _, proto = await self._create_direct_connection(req, traces, timeout)\
  File "/Library/Frameworks/Python.framework/Versions/3.10/lib/python3.10/site-packages/aiohttp/connector.py", line 1209, in _create_direct_connection\
    raise last_exc\
  File "/Library/Frameworks/Python.framework/Versions/3.10/lib/python3.10/site-packages/aiohttp/connector.py", line 1178, in _create_direct_connection\
    transp, proto = await self._wrap_create_connection(\
  File "/Library/Frameworks/Python.framework/Versions/3.10/lib/python3.10/site-packages/aiohttp/connector.py", line 982, in _wrap_create_connection\
    raise ClientConnectorCertificateError(req.connection_key, exc) from exc\
aiohttp.client_exceptions.ClientConnectorCertificateError: Cannot connect to host discord.com:443 ssl:True [SSLCertVerificationError: (1, '[SSL: CERTIFICATE_VERIFY_FAILED] certificate verify failed: unable to get local issuer certificate (_ssl.c:1007)')]\
mf@MFs-MacBook-Air DiscordAWS %  cd /Users/mf/Desktop/IT115/DiscordAWS ; /usr/bin/env /usr/local/bin/python3 /Users/mf/.vscode/extensions/\
ms-python.python-2023.4.1/pythonFiles/lib/python/debugpy/adapter/../../debugpy/launcher 52196 -- /Users/mf/Desktop/IT115/DiscordAWS/main.p\
y \
Traceback (most recent call last):\
  File "/Library/Frameworks/Python.framework/Versions/3.10/lib/python3.10/site-packages/aiohttp/connector.py", line 980, in _wrap_create_connection\
    return await self._loop.create_connection(*args, **kwargs)  # type: ignore[return-value]  # noqa\
  File "/Library/Frameworks/Python.framework/Versions/3.10/lib/python3.10/asyncio/base_events.py", line 1103, in create_connection\
    transport, protocol = await self._create_connection_transport(\
  File "/Library/Frameworks/Python.framework/Versions/3.10/lib/python3.10/asyncio/base_events.py", line 1133, in _create_connection_transport\
    await waiter\
  File "/Library/Frameworks/Python.framework/Versions/3.10/lib/python3.10/asyncio/sslproto.py", line 534, in data_received\
    ssldata, appdata = self._sslpipe.feed_ssldata(data)\
  File "/Library/Frameworks/Python.framework/Versions/3.10/lib/python3.10/asyncio/sslproto.py", line 188, in feed_ssldata\
    self._sslobj.do_handshake()\
  File "/Library/Frameworks/Python.framework/Versions/3.10/lib/python3.10/ssl.py", line 975, in do_handshake\
    self._sslobj.do_handshake()\
ssl.SSLCertVerificationError: [SSL: CERTIFICATE_VERIFY_FAILED] certificate verify failed: unable to get local issuer certificate (_ssl.c:1007)\
\
The above exception was the direct cause of the following exception:\
\
Traceback (most recent call last):\
  File "/Users/mf/Desktop/IT115/DiscordAWS/main.py", line 65, in <module>\
    client.run('MTE2ODE5NTkyNzU2NDA5NTQ4OA.GTTgzQ._UND-IQMgR1HDlOPVEQtpas-y665DBaLLV2qas')\
  File "/Library/Frameworks/Python.framework/Versions/3.10/lib/python3.10/site-packages/discord/client.py", line 668, in run\
    return future.result()\
  File "/Library/Frameworks/Python.framework/Versions/3.10/lib/python3.10/site-packages/discord/client.py", line 647, in runner\
    await self.start(*args, **kwargs)\
  File "/Library/Frameworks/Python.framework/Versions/3.10/lib/python3.10/site-packages/discord/client.py", line 610, in start\
    await self.login(token)\
  File "/Library/Frameworks/Python.framework/Versions/3.10/lib/python3.10/site-packages/discord/client.py", line 478, in login\
    data = await self.http.static_login(token.strip())\
  File "/Library/Frameworks/Python.framework/Versions/3.10/lib/python3.10/site-packages/discord/http.py", line 383, in static_login\
    data = await self.request(Route('GET', '/users/@me'))\
  File "/Library/Frameworks/Python.framework/Versions/3.10/lib/python3.10/site-packages/discord/http.py", line 276, in request\
    async with self.__session.request(method, url, **kwargs) as response:\
  File "/Library/Frameworks/Python.framework/Versions/3.10/lib/python3.10/site-packages/aiohttp/client.py", line 1167, in __aenter__\
    self._resp = await self._coro\
  File "/Library/Frameworks/Python.framework/Versions/3.10/lib/python3.10/site-packages/aiohttp/client.py", line 562, in _request\
    conn = await self._connector.connect(\
  File "/Library/Frameworks/Python.framework/Versions/3.10/lib/python3.10/site-packages/aiohttp/connector.py", line 540, in connect\
    proto = await self._create_connection(req, traces, timeout)\
  File "/Library/Frameworks/Python.framework/Versions/3.10/lib/python3.10/site-packages/aiohttp/connector.py", line 901, in _create_connection\
    _, proto = await self._create_direct_connection(req, traces, timeout)\
  File "/Library/Frameworks/Python.framework/Versions/3.10/lib/python3.10/site-packages/aiohttp/connector.py", line 1209, in _create_direct_connection\
    raise last_exc\
  File "/Library/Frameworks/Python.framework/Versions/3.10/lib/python3.10/site-packages/aiohttp/connector.py", line 1178, in _create_direct_connection\
    transp, proto = await self._wrap_create_connection(\
  File "/Library/Frameworks/Python.framework/Versions/3.10/lib/python3.10/site-packages/aiohttp/connector.py", line 982, in _wrap_create_connection\
    raise ClientConnectorCertificateError(req.connection_key, exc) from exc\
aiohttp.client_exceptions.ClientConnectorCertificateError: Cannot connect to host discord.com:443 ssl:True [SSLCertVerificationError: (1, '[SSL: CERTIFICATE_VERIFY_FAILED] certificate verify failed: unable to get local issuer certificate (_ssl.c:1007)')]\
mf@MFs-MacBook-Air DiscordAWS %  cd /Users/mf/Desktop/IT115/DiscordAWS ; /usr/bin/env /usr/local/bin/python3 /Users/mf/.vscode/extensions/\
ms-python.python-2023.4.1/pythonFiles/lib/python/debugpy/adapter/../../debugpy/launcher 52237 -- /Users/mf/Desktop/IT115/DiscordAWS/main.p\
y \
Traceback (most recent call last):\
  File "/Library/Frameworks/Python.framework/Versions/3.10/lib/python3.10/site-packages/aiohttp/connector.py", line 980, in _wrap_create_connection\
    return await self._loop.create_connection(*args, **kwargs)  # type: ignore[return-value]  # noqa\
  File "/Library/Frameworks/Python.framework/Versions/3.10/lib/python3.10/asyncio/base_events.py", line 1103, in create_connection\
    transport, protocol = await self._create_connection_transport(\
  File "/Library/Frameworks/Python.framework/Versions/3.10/lib/python3.10/asyncio/base_events.py", line 1133, in _create_connection_transport\
    await waiter\
  File "/Library/Frameworks/Python.framework/Versions/3.10/lib/python3.10/asyncio/sslproto.py", line 534, in data_received\
    ssldata, appdata = self._sslpipe.feed_ssldata(data)\
  File "/Library/Frameworks/Python.framework/Versions/3.10/lib/python3.10/asyncio/sslproto.py", line 188, in feed_ssldata\
    self._sslobj.do_handshake()\
  File "/Library/Frameworks/Python.framework/Versions/3.10/lib/python3.10/ssl.py", line 975, in do_handshake\
    self._sslobj.do_handshake()\
ssl.SSLCertVerificationError: [SSL: CERTIFICATE_VERIFY_FAILED] certificate verify failed: unable to get local issuer certificate (_ssl.c:1007)\
\
The above exception was the direct cause of the following exception:\
\
Traceback (most recent call last):\
  File "/Users/mf/Desktop/IT115/DiscordAWS/main.py", line 65, in <module>\
    client.run('MTE2ODE5NTkyNzU2NDA5NTQ4OA.GTTgzQ._UND-IQMgR1HDlOPVEQtpas-y665DBaLLV2qas')\
  File "/Library/Frameworks/Python.framework/Versions/3.10/lib/python3.10/site-packages/discord/client.py", line 668, in run\
    return future.result()\
  File "/Library/Frameworks/Python.framework/Versions/3.10/lib/python3.10/site-packages/discord/client.py", line 647, in runner\
    await self.start(*args, **kwargs)\
  File "/Library/Frameworks/Python.framework/Versions/3.10/lib/python3.10/site-packages/discord/client.py", line 610, in start\
    await self.login(token)\
  File "/Library/Frameworks/Python.framework/Versions/3.10/lib/python3.10/site-packages/discord/client.py", line 478, in login\
    data = await self.http.static_login(token.strip())\
  File "/Library/Frameworks/Python.framework/Versions/3.10/lib/python3.10/site-packages/discord/http.py", line 383, in static_login\
    data = await self.request(Route('GET', '/users/@me'))\
  File "/Library/Frameworks/Python.framework/Versions/3.10/lib/python3.10/site-packages/discord/http.py", line 276, in request\
    async with self.__session.request(method, url, **kwargs) as response:\
  File "/Library/Frameworks/Python.framework/Versions/3.10/lib/python3.10/site-packages/aiohttp/client.py", line 1167, in __aenter__\
    self._resp = await self._coro\
  File "/Library/Frameworks/Python.framework/Versions/3.10/lib/python3.10/site-packages/aiohttp/client.py", line 562, in _request\
    conn = await self._connector.connect(\
  File "/Library/Frameworks/Python.framework/Versions/3.10/lib/python3.10/site-packages/aiohttp/connector.py", line 540, in connect\
    proto = await self._create_connection(req, traces, timeout)\
  File "/Library/Frameworks/Python.framework/Versions/3.10/lib/python3.10/site-packages/aiohttp/connector.py", line 901, in _create_connection\
    _, proto = await self._create_direct_connection(req, traces, timeout)\
  File "/Library/Frameworks/Python.framework/Versions/3.10/lib/python3.10/site-packages/aiohttp/connector.py", line 1209, in _create_direct_connection\
    raise last_exc\
  File "/Library/Frameworks/Python.framework/Versions/3.10/lib/python3.10/site-packages/aiohttp/connector.py", line 1178, in _create_direct_connection\
    transp, proto = await self._wrap_create_connection(\
  File "/Library/Frameworks/Python.framework/Versions/3.10/lib/python3.10/site-packages/aiohttp/connector.py", line 982, in _wrap_create_connection\
    raise ClientConnectorCertificateError(req.connection_key, exc) from exc\
aiohttp.client_exceptions.ClientConnectorCertificateError: Cannot connect to host discord.com:443 ssl:True [SSLCertVerificationError: (1, '[SSL: CERTIFICATE_VERIFY_FAILED] certificate verify failed: unable to get local issuer certificate (_ssl.c:1007)')]\
mf@MFs-MacBook-Air DiscordAWS %  cd /Users/mf/Desktop/IT115/DiscordAWS ; /usr/bin/env /usr/bin/python3 /Users/mf/.vscode/extensions/ms-pyt\
hon.python-2023.4.1/pythonFiles/lib/python/debugpy/adapter/../../debugpy/launcher 52539 -- /Users/mf/Desktop/IT115/DiscordAWS/main.py \
Traceback (most recent call last):\
  File "/Users/mf/Desktop/IT115/DiscordAWS/main.py", line 4, in <module>\
    import discord\
ModuleNotFoundError: No module named 'discord'\
mf@MFs-MacBook-Air DiscordAWS %  cd /Users/mf/Desktop/IT115/DiscordAWS ; /usr/bin/env /usr/local/bin/python3 /Users/mf/.vscode/extensions/\
ms-python.python-2023.4.1/pythonFiles/lib/python/debugpy/adapter/../../debugpy/launcher 52632 -- /Users/mf/Desktop/IT115/DiscordAWS/main.p\
y \
Traceback (most recent call last):\
  File "/Library/Frameworks/Python.framework/Versions/3.10/lib/python3.10/site-packages/aiohttp/connector.py", line 980, in _wrap_create_connection\
    return await self._loop.create_connection(*args, **kwargs)  # type: ignore[return-value]  # noqa\
  File "/Library/Frameworks/Python.framework/Versions/3.10/lib/python3.10/asyncio/base_events.py", line 1103, in create_connection\
    transport, protocol = await self._create_connection_transport(\
  File "/Library/Frameworks/Python.framework/Versions/3.10/lib/python3.10/asyncio/base_events.py", line 1133, in _create_connection_transport\
    await waiter\
  File "/Library/Frameworks/Python.framework/Versions/3.10/lib/python3.10/asyncio/sslproto.py", line 534, in data_received\
    ssldata, appdata = self._sslpipe.feed_ssldata(data)\
  File "/Library/Frameworks/Python.framework/Versions/3.10/lib/python3.10/asyncio/sslproto.py", line 188, in feed_ssldata\
    self._sslobj.do_handshake()\
  File "/Library/Frameworks/Python.framework/Versions/3.10/lib/python3.10/ssl.py", line 975, in do_handshake\
    self._sslobj.do_handshake()\
ssl.SSLCertVerificationError: [SSL: CERTIFICATE_VERIFY_FAILED] certificate verify failed: unable to get local issuer certificate (_ssl.c:1007)\
\
The above exception was the direct cause of the following exception:\
\
Traceback (most recent call last):\
  File "/Users/mf/Desktop/IT115/DiscordAWS/main.py", line 65, in <module>\
    client.run('MTE2ODE5NTkyNzU2NDA5NTQ4OA.GTTgzQ._UND-IQMgR1HDlOPVEQtpas-y665DBaLLV2qas')\
  File "/Library/Frameworks/Python.framework/Versions/3.10/lib/python3.10/site-packages/discord/client.py", line 668, in run\
    return future.result()\
  File "/Library/Frameworks/Python.framework/Versions/3.10/lib/python3.10/site-packages/discord/client.py", line 647, in runner\
    await self.start(*args, **kwargs)\
  File "/Library/Frameworks/Python.framework/Versions/3.10/lib/python3.10/site-packages/discord/client.py", line 610, in start\
    await self.login(token)\
  File "/Library/Frameworks/Python.framework/Versions/3.10/lib/python3.10/site-packages/discord/client.py", line 478, in login\
    data = await self.http.static_login(token.strip())\
  File "/Library/Frameworks/Python.framework/Versions/3.10/lib/python3.10/site-packages/discord/http.py", line 383, in static_login\
    data = await self.request(Route('GET', '/users/@me'))\
  File "/Library/Frameworks/Python.framework/Versions/3.10/lib/python3.10/site-packages/discord/http.py", line 276, in request\
    async with self.__session.request(method, url, **kwargs) as response:\
  File "/Library/Frameworks/Python.framework/Versions/3.10/lib/python3.10/site-packages/aiohttp/client.py", line 1167, in __aenter__\
    self._resp = await self._coro\
  File "/Library/Frameworks/Python.framework/Versions/3.10/lib/python3.10/site-packages/aiohttp/client.py", line 562, in _request\
    conn = await self._connector.connect(\
  File "/Library/Frameworks/Python.framework/Versions/3.10/lib/python3.10/site-packages/aiohttp/connector.py", line 540, in connect\
    proto = await self._create_connection(req, traces, timeout)\
  File "/Library/Frameworks/Python.framework/Versions/3.10/lib/python3.10/site-packages/aiohttp/connector.py", line 901, in _create_connection\
    _, proto = await self._create_direct_connection(req, traces, timeout)\
  File "/Library/Frameworks/Python.framework/Versions/3.10/lib/python3.10/site-packages/aiohttp/connector.py", line 1209, in _create_direct_connection\
    raise last_exc\
  File "/Library/Frameworks/Python.framework/Versions/3.10/lib/python3.10/site-packages/aiohttp/connector.py", line 1178, in _create_direct_connection\
    transp, proto = await self._wrap_create_connection(\
  File "/Library/Frameworks/Python.framework/Versions/3.10/lib/python3.10/site-packages/aiohttp/connector.py", line 982, in _wrap_create_connection\
    raise ClientConnectorCertificateError(req.connection_key, exc) from exc\
aiohttp.client_exceptions.ClientConnectorCertificateError: Cannot connect to host discord.com:443 ssl:True [SSLCertVerificationError: (1, '[SSL: CERTIFICATE_VERIFY_FAILED] certificate verify failed: unable to get local issuer certificate (_ssl.c:1007)')]\
mf@MFs-MacBook-Air DiscordAWS %  cd /Users/mf/Desktop/IT115/DiscordAWS ; /usr/bin/env /usr/local/bin/python3 /Users/mf/.vscode/extensions/\
ms-python.python-2023.4.1/pythonFiles/lib/python/debugpy/adapter/../../debugpy/launcher 53233 -- /Users/mf/Desktop/IT115/DiscordAWS/main.p\
y \
Ignoring exception in on_connect\
Traceback (most recent call last):\
  File "/Library/Frameworks/Python.framework/Versions/3.10/lib/python3.10/site-packages/discord/client.py", line 352, in _run_event\
    await coro(*args, **kwargs)\
  File "/Library/Frameworks/Python.framework/Versions/3.10/lib/python3.10/site-packages/discord/bot.py", line 793, in on_connect\
    await self.register_commands()\
  File "/Library/Frameworks/Python.framework/Versions/3.10/lib/python3.10/site-packages/discord/bot.py", line 460, in register_commands\
    await self.http.bulk_upsert_command_permissions(\
  File "/Library/Frameworks/Python.framework/Versions/3.10/lib/python3.10/site-packages/discord/http.py", line 338, in request\
    raise HTTPException(response, data)\
discord.errors.HTTPException: 405 Method Not Allowed (error code: 0): 405: Method Not Allowed\
Logged in as a bot Testing2#5280\
Message hello by marcusholloway_ on random\
Message Hello marcusholloway_ by Testing2 on random\
Message bye by marcusholloway_ on random\
Message Bye marcusholloway_ by Testing2 on random\
}